2025-08-01 18:48:10.796 WARNING (SyncWorker_0) [homeassistant.loader] We found a custom integration dwains_dashboard which has not been tested by Home Assistant. This component might cause stability problems, be sure to disable it if you experience issues with Home Assistant
2025-08-01 18:48:10.797 WARNING (SyncWorker_0) [homeassistant.loader] We found a custom integration hacs which has not been tested by Home Assistant. This component might cause stability problems, be sure to disable it if you experience issues with Home Assistant
2025-08-01 18:48:15.011 ERROR (SyncWorker_2) [homeassistant.components.camera.img_util] Error loading libturbojpeg; Camera snapshot performance will be sub-optimal
Traceback (most recent call last):
  File "/usr/src/homeassistant/homeassistant/components/camera/img_util.py", line 93, in __init__
    TurboJPEGSingleton.__instance = TurboJPEG()
                                    ~~~~~~~~~^^
  File "/usr/local/lib/python3.13/site-packages/turbojpeg.py", line 300, in __init__
    turbo_jpeg = cdll.LoadLibrary(
        self.__find_turbojpeg() if lib_path is None else lib_path)
  File "/usr/local/lib/python3.13/ctypes/__init__.py", line 471, in LoadLibrary
    return self._dlltype(name)
           ~~~~~~~~~~~~~^^^^^^
  File "/usr/local/lib/python3.13/ctypes/__init__.py", line 390, in __init__
    self._handle = _dlopen(self._name, mode)
                   ~~~~~~~^^^^^^^^^^^^^^^^^^
OSError: Error loading shared library /usr/lib/libturbojpeg.so.0: Exec format error
2025-08-01 18:48:17.792 WARNING (MainThread) [homeassistant.util.loop] Detected blocking call to load_default_certs with args (<ssl.SSLContext object at 0x7f8e2ba8d0>, <Purpose.SERVER_AUTH: _ASN1Object(nid=129, shortname='serverAuth', longname='TLS Web Server Authentication', oid='1.3.6.1.5.5.7.3.1')>) inside the event loop by integration 'freebox' at homeassistant/components/freebox/__init__.py, line 22: await api.open(entry.data[CONF_HOST], entry.data[CONF_PORT]) (offender: /usr/local/lib/python3.13/ssl.py, line 722: context.load_default_certs(purpose)), please create a bug report at https://github.com/home-assistant/core/issues?q=is%3Aopen+is%3Aissue+label%3A%22integration%3A+freebox%22
For developers, please see https://developers.home-assistant.io/docs/asyncio_blocking_operations/#load_default_certs
Traceback (most recent call last):
  File "<frozen runpy>", line 198, in _run_module_as_main
  File "<frozen runpy>", line 88, in _run_code
  File "/usr/src/homeassistant/homeassistant/__main__.py", line 223, in <module>
    sys.exit(main())
  File "/usr/src/homeassistant/homeassistant/__main__.py", line 209, in main
    exit_code = runner.run(runtime_conf)
  File "/usr/src/homeassistant/homeassistant/runner.py", line 154, in run
    return loop.run_until_complete(setup_and_run_hass(runtime_config))
  File "/usr/local/lib/python3.13/asyncio/base_events.py", line 706, in run_until_complete
    self.run_forever()
  File "/usr/local/lib/python3.13/asyncio/base_events.py", line 677, in run_forever
    self._run_once()
  File "/usr/local/lib/python3.13/asyncio/base_events.py", line 2034, in _run_once
    handle._run()
  File "/usr/local/lib/python3.13/asyncio/events.py", line 89, in _run
    self._context.run(self._callback, *self._args)
  File "/usr/src/homeassistant/homeassistant/setup.py", line 170, in async_setup_component
    result = await _async_setup_component(hass, domain, config)
  File "/usr/src/homeassistant/homeassistant/setup.py", line 470, in _async_setup_component
    await asyncio.gather(
  File "/usr/src/homeassistant/homeassistant/setup.py", line 472, in <genexpr>
    create_eager_task(
  File "/usr/src/homeassistant/homeassistant/util/async_.py", line 44, in create_eager_task
    return Task(coro, loop=loop, name=name, eager_start=True)
  File "/usr/src/homeassistant/homeassistant/config_entries.py", line 894, in async_setup_locked
    await self.async_setup(hass, integration=integration)
  File "/usr/src/homeassistant/homeassistant/config_entries.py", line 660, in async_setup
    await self.__async_setup_with_context(hass, integration)
  File "/usr/src/homeassistant/homeassistant/config_entries.py", line 749, in __async_setup_with_context
    result = await component.async_setup_entry(hass, self)
  File "/usr/src/homeassistant/homeassistant/components/freebox/__init__.py", line 22, in async_setup_entry
    await api.open(entry.data[CONF_HOST], entry.data[CONF_PORT])

2025-08-01 18:48:17.796 WARNING (MainThread) [homeassistant.util.loop] Detected blocking call to set_default_verify_paths with args (<ssl.SSLContext object at 0x7f8e2ba8d0>,) inside the event loop by integration 'freebox' at homeassistant/components/freebox/__init__.py, line 22: await api.open(entry.data[CONF_HOST], entry.data[CONF_PORT]) (offender: /usr/local/lib/python3.13/ssl.py, line 534: self.set_default_verify_paths()), please create a bug report at https://github.com/home-assistant/core/issues?q=is%3Aopen+is%3Aissue+label%3A%22integration%3A+freebox%22
For developers, please see https://developers.home-assistant.io/docs/asyncio_blocking_operations/#set_default_verify_paths
Traceback (most recent call last):
  File "<frozen runpy>", line 198, in _run_module_as_main
  File "<frozen runpy>", line 88, in _run_code
  File "/usr/src/homeassistant/homeassistant/__main__.py", line 223, in <module>
    sys.exit(main())
  File "/usr/src/homeassistant/homeassistant/__main__.py", line 209, in main
    exit_code = runner.run(runtime_conf)
  File "/usr/src/homeassistant/homeassistant/runner.py", line 154, in run
    return loop.run_until_complete(setup_and_run_hass(runtime_config))
  File "/usr/local/lib/python3.13/asyncio/base_events.py", line 706, in run_until_complete
    self.run_forever()
  File "/usr/local/lib/python3.13/asyncio/base_events.py", line 677, in run_forever
    self._run_once()
  File "/usr/local/lib/python3.13/asyncio/base_events.py", line 2034, in _run_once
    handle._run()
  File "/usr/local/lib/python3.13/asyncio/events.py", line 89, in _run
    self._context.run(self._callback, *self._args)
  File "/usr/src/homeassistant/homeassistant/setup.py", line 170, in async_setup_component
    result = await _async_setup_component(hass, domain, config)
  File "/usr/src/homeassistant/homeassistant/setup.py", line 470, in _async_setup_component
    await asyncio.gather(
  File "/usr/src/homeassistant/homeassistant/setup.py", line 472, in <genexpr>
    create_eager_task(
  File "/usr/src/homeassistant/homeassistant/util/async_.py", line 44, in create_eager_task
    return Task(coro, loop=loop, name=name, eager_start=True)
  File "/usr/src/homeassistant/homeassistant/config_entries.py", line 894, in async_setup_locked
    await self.async_setup(hass, integration=integration)
  File "/usr/src/homeassistant/homeassistant/config_entries.py", line 660, in async_setup
    await self.__async_setup_with_context(hass, integration)
  File "/usr/src/homeassistant/homeassistant/config_entries.py", line 749, in __async_setup_with_context
    result = await component.async_setup_entry(hass, self)
  File "/usr/src/homeassistant/homeassistant/components/freebox/__init__.py", line 22, in async_setup_entry
    await api.open(entry.data[CONF_HOST], entry.data[CONF_PORT])

2025-08-01 18:48:17.817 WARNING (MainThread) [homeassistant.util.loop] Detected blocking call to load_verify_locations with args (<ssl.SSLContext object at 0x7f8e2ba8d0>,) inside the event loop by integration 'freebox' at homeassistant/components/freebox/__init__.py, line 22: await api.open(entry.data[CONF_HOST], entry.data[CONF_PORT]) (offender: /usr/local/lib/python3.13/site-packages/freebox_api/aiofreepybox.py, line 124: ssl_ctx.load_verify_locations(cafile=cert_path)), please create a bug report at https://github.com/home-assistant/core/issues?q=is%3Aopen+is%3Aissue+label%3A%22integration%3A+freebox%22
For developers, please see https://developers.home-assistant.io/docs/asyncio_blocking_operations/#load_verify_locations
Traceback (most recent call last):
  File "<frozen runpy>", line 198, in _run_module_as_main
  File "<frozen runpy>", line 88, in _run_code
  File "/usr/src/homeassistant/homeassistant/__main__.py", line 223, in <module>
    sys.exit(main())
  File "/usr/src/homeassistant/homeassistant/__main__.py", line 209, in main
    exit_code = runner.run(runtime_conf)
  File "/usr/src/homeassistant/homeassistant/runner.py", line 154, in run
    return loop.run_until_complete(setup_and_run_hass(runtime_config))
  File "/usr/local/lib/python3.13/asyncio/base_events.py", line 706, in run_until_complete
    self.run_forever()
  File "/usr/local/lib/python3.13/asyncio/base_events.py", line 677, in run_forever
    self._run_once()
  File "/usr/local/lib/python3.13/asyncio/base_events.py", line 2034, in _run_once
    handle._run()
  File "/usr/local/lib/python3.13/asyncio/events.py", line 89, in _run
    self._context.run(self._callback, *self._args)
  File "/usr/src/homeassistant/homeassistant/setup.py", line 170, in async_setup_component
    result = await _async_setup_component(hass, domain, config)
  File "/usr/src/homeassistant/homeassistant/setup.py", line 470, in _async_setup_component
    await asyncio.gather(
  File "/usr/src/homeassistant/homeassistant/setup.py", line 472, in <genexpr>
    create_eager_task(
  File "/usr/src/homeassistant/homeassistant/util/async_.py", line 44, in create_eager_task
    return Task(coro, loop=loop, name=name, eager_start=True)
  File "/usr/src/homeassistant/homeassistant/config_entries.py", line 894, in async_setup_locked
    await self.async_setup(hass, integration=integration)
  File "/usr/src/homeassistant/homeassistant/config_entries.py", line 660, in async_setup
    await self.__async_setup_with_context(hass, integration)
  File "/usr/src/homeassistant/homeassistant/config_entries.py", line 749, in __async_setup_with_context
    result = await component.async_setup_entry(hass, self)
  File "/usr/src/homeassistant/homeassistant/components/freebox/__init__.py", line 22, in async_setup_entry
    await api.open(entry.data[CONF_HOST], entry.data[CONF_PORT])

2025-08-01 18:48:17.822 WARNING (MainThread) [homeassistant.util.loop] Detected blocking call to open with args (PosixPath('/config/.storage/freebox/2y52zdio_fbxos_fr.conf'), 'r') inside the event loop by integration 'freebox' at homeassistant/components/freebox/__init__.py, line 22: await api.open(entry.data[CONF_HOST], entry.data[CONF_PORT]) (offender: /usr/local/lib/python3.13/site-packages/freebox_api/aiofreepybox.py, line 328: with open(token_file, "r") as f:), please create a bug report at https://github.com/home-assistant/core/issues?q=is%3Aopen+is%3Aissue+label%3A%22integration%3A+freebox%22
For developers, please see https://developers.home-assistant.io/docs/asyncio_blocking_operations/#open
Traceback (most recent call last):
  File "<frozen runpy>", line 198, in _run_module_as_main
  File "<frozen runpy>", line 88, in _run_code
  File "/usr/src/homeassistant/homeassistant/__main__.py", line 223, in <module>
    sys.exit(main())
  File "/usr/src/homeassistant/homeassistant/__main__.py", line 209, in main
    exit_code = runner.run(runtime_conf)
  File "/usr/src/homeassistant/homeassistant/runner.py", line 154, in run
    return loop.run_until_complete(setup_and_run_hass(runtime_config))
  File "/usr/local/lib/python3.13/asyncio/base_events.py", line 706, in run_until_complete
    self.run_forever()
  File "/usr/local/lib/python3.13/asyncio/base_events.py", line 677, in run_forever
    self._run_once()
  File "/usr/local/lib/python3.13/asyncio/base_events.py", line 2034, in _run_once
    handle._run()
  File "/usr/local/lib/python3.13/asyncio/events.py", line 89, in _run
    self._context.run(self._callback, *self._args)
  File "/usr/src/homeassistant/homeassistant/setup.py", line 170, in async_setup_component
    result = await _async_setup_component(hass, domain, config)
  File "/usr/src/homeassistant/homeassistant/setup.py", line 470, in _async_setup_component
    await asyncio.gather(
  File "/usr/src/homeassistant/homeassistant/setup.py", line 472, in <genexpr>
    create_eager_task(
  File "/usr/src/homeassistant/homeassistant/util/async_.py", line 44, in create_eager_task
    return Task(coro, loop=loop, name=name, eager_start=True)
  File "/usr/src/homeassistant/homeassistant/config_entries.py", line 894, in async_setup_locked
    await self.async_setup(hass, integration=integration)
  File "/usr/src/homeassistant/homeassistant/config_entries.py", line 660, in async_setup
    await self.__async_setup_with_context(hass, integration)
  File "/usr/src/homeassistant/homeassistant/config_entries.py", line 749, in __async_setup_with_context
    result = await component.async_setup_entry(hass, self)
  File "/usr/src/homeassistant/homeassistant/components/freebox/__init__.py", line 22, in async_setup_entry
    await api.open(entry.data[CONF_HOST], entry.data[CONF_PORT])

2025-08-01 18:48:17.965 WARNING (MainThread) [homeassistant.components.freebox.router] Home access is not granted
2025-08-01 18:48:25.872 WARNING (ImportExecutor_0) [py.warnings] /usr/local/lib/python3.13/site-packages/google/__init__.py:2: UserWarning: pkg_resources is deprecated as an API. See https://setuptools.pypa.io/en/latest/pkg_resources.html. The pkg_resources package is slated for removal as early as 2025-11-30. Refrain from using this package or pin to Setuptools<81.
  __import__('pkg_resources').declare_namespace(__name__)

2025-08-01 18:48:26.927 ERROR (SyncWorker_5) [aiodhcpwatcher] Cannot watch for dhcp packets without a functional packet filter: libpcap is not available. Cannot compile filter !
2025-08-01 18:48:31.727 WARNING (ImportExecutor_0) [py.warnings] /usr/local/lib/python3.13/site-packages/google/protobuf/runtime_version.py:98: UserWarning: Protobuf gencode version 5.28.1 is exactly one major version older than the runtime version 6.31.1 at pyatv/protocols/mrp/protobuf/ProtocolMessage.proto. Please update the gencode to avoid compatibility violations in the next runtime release.
  warnings.warn(

2025-08-01 18:48:31.730 WARNING (ImportExecutor_0) [py.warnings] /usr/local/lib/python3.13/site-packages/google/protobuf/runtime_version.py:98: UserWarning: Protobuf gencode version 5.28.1 is exactly one major version older than the runtime version 6.31.1 at pyatv/protocols/mrp/protobuf/AudioFadeMessage.proto. Please update the gencode to avoid compatibility violations in the next runtime release.
  warnings.warn(

2025-08-01 18:48:31.733 WARNING (ImportExecutor_0) [py.warnings] /usr/local/lib/python3.13/site-packages/google/protobuf/runtime_version.py:98: UserWarning: Protobuf gencode version 5.28.1 is exactly one major version older than the runtime version 6.31.1 at pyatv/protocols/mrp/protobuf/PlayerPath.proto. Please update the gencode to avoid compatibility violations in the next runtime release.
  warnings.warn(

2025-08-01 18:48:31.735 WARNING (ImportExecutor_0) [py.warnings] /usr/local/lib/python3.13/site-packages/google/protobuf/runtime_version.py:98: UserWarning: Protobuf gencode version 5.28.1 is exactly one major version older than the runtime version 6.31.1 at pyatv/protocols/mrp/protobuf/Origin.proto. Please update the gencode to avoid compatibility violations in the next runtime release.
  warnings.warn(

2025-08-01 18:48:31.737 WARNING (ImportExecutor_0) [py.warnings] /usr/local/lib/python3.13/site-packages/google/protobuf/runtime_version.py:98: UserWarning: Protobuf gencode version 5.28.1 is exactly one major version older than the runtime version 6.31.1 at pyatv/protocols/mrp/protobuf/DeviceInfoMessage.proto. Please update the gencode to avoid compatibility violations in the next runtime release.
  warnings.warn(

2025-08-01 18:48:31.740 WARNING (ImportExecutor_0) [py.warnings] /usr/local/lib/python3.13/site-packages/google/protobuf/runtime_version.py:98: UserWarning: Protobuf gencode version 5.28.1 is exactly one major version older than the runtime version 6.31.1 at pyatv/protocols/mrp/protobuf/Common.proto. Please update the gencode to avoid compatibility violations in the next runtime release.
  warnings.warn(

2025-08-01 18:48:31.743 WARNING (ImportExecutor_0) [py.warnings] /usr/local/lib/python3.13/site-packages/google/protobuf/runtime_version.py:98: UserWarning: Protobuf gencode version 5.28.1 is exactly one major version older than the runtime version 6.31.1 at pyatv/protocols/mrp/protobuf/NowPlayingClient.proto. Please update the gencode to avoid compatibility violations in the next runtime release.
  warnings.warn(

2025-08-01 18:48:31.745 WARNING (ImportExecutor_0) [py.warnings] /usr/local/lib/python3.13/site-packages/google/protobuf/runtime_version.py:98: UserWarning: Protobuf gencode version 5.28.1 is exactly one major version older than the runtime version 6.31.1 at pyatv/protocols/mrp/protobuf/NowPlayingPlayer.proto. Please update the gencode to avoid compatibility violations in the next runtime release.
  warnings.warn(

2025-08-01 18:48:31.748 WARNING (ImportExecutor_0) [py.warnings] /usr/local/lib/python3.13/site-packages/google/protobuf/runtime_version.py:98: UserWarning: Protobuf gencode version 5.28.1 is exactly one major version older than the runtime version 6.31.1 at pyatv/protocols/mrp/protobuf/AudioFadeResponseMessage.proto. Please update the gencode to avoid compatibility violations in the next runtime release.
  warnings.warn(

2025-08-01 18:48:31.750 WARNING (ImportExecutor_0) [py.warnings] /usr/local/lib/python3.13/site-packages/google/protobuf/runtime_version.py:98: UserWarning: Protobuf gencode version 5.28.1 is exactly one major version older than the runtime version 6.31.1 at pyatv/protocols/mrp/protobuf/ClientUpdatesConfigMessage.proto. Please update the gencode to avoid compatibility violations in the next runtime release.
  warnings.warn(

2025-08-01 18:48:31.752 WARNING (ImportExecutor_0) [py.warnings] /usr/local/lib/python3.13/site-packages/google/protobuf/runtime_version.py:98: UserWarning: Protobuf gencode version 5.28.1 is exactly one major version older than the runtime version 6.31.1 at pyatv/protocols/mrp/protobuf/ConfigureConnectionMessage.proto. Please update the gencode to avoid compatibility violations in the next runtime release.
  warnings.warn(

2025-08-01 18:48:31.755 WARNING (ImportExecutor_0) [py.warnings] /usr/local/lib/python3.13/site-packages/google/protobuf/runtime_version.py:98: UserWarning: Protobuf gencode version 5.28.1 is exactly one major version older than the runtime version 6.31.1 at pyatv/protocols/mrp/protobuf/CryptoPairingMessage.proto. Please update the gencode to avoid compatibility violations in the next runtime release.
  warnings.warn(

2025-08-01 18:48:31.757 WARNING (ImportExecutor_0) [py.warnings] /usr/local/lib/python3.13/site-packages/google/protobuf/runtime_version.py:98: UserWarning: Protobuf gencode version 5.28.1 is exactly one major version older than the runtime version 6.31.1 at pyatv/protocols/mrp/protobuf/GenericMessage.proto. Please update the gencode to avoid compatibility violations in the next runtime release.
  warnings.warn(

2025-08-01 18:48:31.759 WARNING (ImportExecutor_0) [py.warnings] /usr/local/lib/python3.13/site-packages/google/protobuf/runtime_version.py:98: UserWarning: Protobuf gencode version 5.28.1 is exactly one major version older than the runtime version 6.31.1 at pyatv/protocols/mrp/protobuf/GetKeyboardSessionMessage.proto. Please update the gencode to avoid compatibility violations in the next runtime release.
  warnings.warn(

2025-08-01 18:48:31.761 WARNING (ImportExecutor_0) [py.warnings] /usr/local/lib/python3.13/site-packages/google/protobuf/runtime_version.py:98: UserWarning: Protobuf gencode version 5.28.1 is exactly one major version older than the runtime version 6.31.1 at pyatv/protocols/mrp/protobuf/GetRemoteTextInputSessionMessage.proto. Please update the gencode to avoid compatibility violations in the next runtime release.
  warnings.warn(

2025-08-01 18:48:31.763 WARNING (ImportExecutor_0) [py.warnings] /usr/local/lib/python3.13/site-packages/google/protobuf/runtime_version.py:98: UserWarning: Protobuf gencode version 5.28.1 is exactly one major version older than the runtime version 6.31.1 at pyatv/protocols/mrp/protobuf/GetVolumeMessage.proto. Please update the gencode to avoid compatibility violations in the next runtime release.
  warnings.warn(

2025-08-01 18:48:31.765 WARNING (ImportExecutor_0) [py.warnings] /usr/local/lib/python3.13/site-packages/google/protobuf/runtime_version.py:98: UserWarning: Protobuf gencode version 5.28.1 is exactly one major version older than the runtime version 6.31.1 at pyatv/protocols/mrp/protobuf/GetVolumeResultMessage.proto. Please update the gencode to avoid compatibility violations in the next runtime release.
  warnings.warn(

2025-08-01 18:48:31.768 WARNING (ImportExecutor_0) [py.warnings] /usr/local/lib/python3.13/site-packages/google/protobuf/runtime_version.py:98: UserWarning: Protobuf gencode version 5.28.1 is exactly one major version older than the runtime version 6.31.1 at pyatv/protocols/mrp/protobuf/KeyboardMessage.proto. Please update the gencode to avoid compatibility violations in the next runtime release.
  warnings.warn(

2025-08-01 18:48:31.771 WARNING (ImportExecutor_0) [py.warnings] /usr/local/lib/python3.13/site-packages/google/protobuf/runtime_version.py:98: UserWarning: Protobuf gencode version 5.28.1 is exactly one major version older than the runtime version 6.31.1 at pyatv/protocols/mrp/protobuf/ModifyOutputContextRequestMessage.proto. Please update the gencode to avoid compatibility violations in the next runtime release.
  warnings.warn(

2025-08-01 18:48:31.773 WARNING (ImportExecutor_0) [py.warnings] /usr/local/lib/python3.13/site-packages/google/protobuf/runtime_version.py:98: UserWarning: Protobuf gencode version 5.28.1 is exactly one major version older than the runtime version 6.31.1 at pyatv/protocols/mrp/protobuf/NotificationMessage.proto. Please update the gencode to avoid compatibility violations in the next runtime release.
  warnings.warn(

2025-08-01 19:18:02.356 ERROR (MainThread) [homeassistant.components.hassio] Failed to to call /store/repositories - Cmd('git') failed due to: exit code(128)
  cmdline: git clone -v --recursive --depth=1 --shallow-submodules -- https://hub.docker.com/r/jlesage/firefox /data/addons/git/33e60433
  stderr: 'Cloning into '/data/addons/git/33e60433'...
fatal: repository 'https://hub.docker.com/r/jlesage/firefox/' not found
'
2025-08-01 19:18:27.098 ERROR (MainThread) [homeassistant.components.hassio] Failed to to call /store/repositories - expected a URL for dictionary value @ data['repository']. Got 'sha256:595d0584e079187b35b6d67fd3fb98779c13d2a4e95314b0e0e489c191dd5112'
2025-08-01 19:19:13.492 ERROR (MainThread) [homeassistant.components.hassio] Failed to to call /store/repositories - https://github.com/jlesage/docker-firefox is not a valid add-on repository
2025-08-01 19:39:29.011 WARNING (MainThread) [homeassistant.components.http.ban] Login attempt or request with invalid authentication from fe80::92:d042:816b:3a8e (fe80::92:d042:816b:3a8e). Requested URL: '/api/config'. (Home Assistant/1.5.1 (io.robbie.HomeAssistant; build:4; iOS 9.3.5) Alamofire/4.7.3)
2025-08-01 19:40:17.967 WARNING (MainThread) [homeassistant.components.http.ban] Login attempt or request with invalid authentication from 192.168.1.136 (192.168.1.136). Requested URL: '/api/config'. (Home Assistant/1.5.1 (io.robbie.HomeAssistant; build:4; iOS 9.3.5) Alamofire/4.7.3)
2025-08-01 19:46:36.333 WARNING (MainThread) [homeassistant.components.http.ban] Login attempt or request with invalid authentication from fe80::92:d042:816b:3a8e (fe80::92:d042:816b:3a8e). Requested URL: '/api/config'. (Home Assistant/1.5.1 (io.robbie.HomeAssistant; build:4; iOS 9.3.5) Alamofire/4.7.3)
2025-08-01 19:55:35.782 WARNING (MainThread) [homeassistant.components.http.ban] Login attempt or request with invalid authentication from 192.168.1.136 (192.168.1.136). Requested URL: '/api/config'. (Home Assistant/1.5.1 (io.robbie.HomeAssistant; build:4; iOS 9.3.5) Alamofire/4.7.3)
